from django.core.exceptions import ValidationError

def validate_brawler_name(self):
    pass